#VRML_SIM R2025a utf8

EXTERNPROTO "https://raw.githubusercontent.com/cyberbotics/webots/R2025a/projects/objects/backgrounds/protos/TexturedBackground.proto"
EXTERNPROTO "https://raw.githubusercontent.com/cyberbotics/webots/R2025a/projects/objects/backgrounds/protos/TexturedBackgroundLight.proto"
EXTERNPROTO "https://raw.githubusercontent.com/cyberbotics/webots/R2025a/projects/objects/floors/protos/Floor.proto"
EXTERNPROTO "https://raw.githubusercontent.com/cyberbotics/webots/R2025a/projects/samples/robotbenchmark/wall_following/protos/WallFollowingPioneer3dx.proto"
EXTERNPROTO "https://raw.githubusercontent.com/cyberbotics/webots/R2025a/projects/devices/sick/protos/SickLms291.proto"
EXTERNPROTO "https://raw.githubusercontent.com/cyberbotics/webots/R2025a/projects/devices/microsoft/protos/Kinect.proto"
EXTERNPROTO "https://raw.githubusercontent.com/cyberbotics/webots/R2025a/projects/robots/mir/mir100/protos/Mir100UltrasonicSensor.proto"
EXTERNPROTO "https://raw.githubusercontent.com/cyberbotics/webots/R2025a/projects/devices/sharp/protos/SharpGP2Y0A41SK0F.proto"
EXTERNPROTO "https://raw.githubusercontent.com/cyberbotics/webots/R2025a/projects/objects/apartment_structure/protos/Wall.proto"
EXTERNPROTO "https://raw.githubusercontent.com/cyberbotics/webots/R2025a/projects/objects/tables/protos/Table.proto"
EXTERNPROTO "https://raw.githubusercontent.com/cyberbotics/webots/R2025a/projects/objects/chairs/protos/Chair.proto"

WorldInfo {
}
Viewpoint {
  orientation -0.2605853064597014 0.13232857595355832 0.9563390852848203 2.23741387689498
  position 12.332677677819895 -15.196132089807275 12.411457537598881
  follow "floor"
  followType "Mounted Shot"
}
TexturedBackground {
}
TexturedBackgroundLight {
}
Floor {
  size 20 20
}
Table {
  translation 6.71 5.83 0
}
Table {
  translation 7 -1.15 0
  name "table(1)"
}
Table {
  translation -7.76 6.38 0
  name "table(2)"
}
Table {
  translation -7.37 -0.39 0
  name "table(3)"
}
Chair {
  translation 7.44 6.46 0
  rotation 0 0 1 3.14159
}
Chair {
  translation 7.48 5.42 0
  rotation 0 0 1 3.14159
  name "chair(1)"
}
Chair {
  translation 5.5 6.33 -0.04
  rotation 0 0 1 -5.307179586466759e-06
  name "chair(8)"
}
Chair {
  translation 5.62 5.61 -0.04
  rotation 0 0 1 -5.307179586466759e-06
  name "chair(9)"
}
Chair {
  translation 6.06 -1.54 -0.04
  rotation 0 0 1 -5.307179586466759e-06
  name "chair(10)"
}
Chair {
  translation 5.95 -0.780015 -0.04
  rotation 0 0 1 -5.307179586466759e-06
  name "chair(11)"
}
Chair {
  translation -8.67 5.43 -0.04
  rotation 0 0 1 -5.307179586466759e-06
  name "chair(12)"
}
Chair {
  translation -8.72 6.85 -0.04
  rotation 0 0 1 -5.307179586466759e-06
  name "chair(13)"
}
Chair {
  translation -8.15 -0.84999 -0.04
  rotation 0 0 1 -5.307179586466759e-06
  name "chair(14)"
}
Chair {
  translation -8.18 0.170036 -0.04
  rotation 0 0 1 -5.307179586466759e-06
  name "chair(15)"
}
Chair {
  translation -6.87 6.54 0
  rotation 0 0 1 3.14159
  name "chair(2)"
}
Chair {
  translation 7.92 -1.92 0
  rotation 0 0 1 3.14159
  name "chair(4)"
}
Chair {
  translation 7.87 -0.750004 0
  rotation 0 0 1 3.14159
  name "chair(5)"
}
Chair {
  translation -6.48 -0.0399991 0
  rotation 0 0 1 3.14159
  name "chair(6)"
}
Chair {
  translation -6.29 -0.96999 0
  rotation 0 0 1 3.14159
  name "chair(7)"
}
Chair {
  translation -6.95 5.64 0
  rotation 0 0 1 3.14159
  name "chair(3)"
}
Wall {
  translation -3.76 3.58 0.479999
  rotation 1 0 0 1.5708
  size 0.1 1 5
}
Wall {
  translation 2.9 3.58 0.479999
  rotation 1 0 0 1.5708
  name "wall(5)"
  size 0.1 1 5
}
Wall {
  translation -4.15 -5.24 0.479991
  rotation 1 0 0 1.5708
  name "wall(1)"
  size 0.1 1 5
}
Wall {
  translation 3.27 9.98 0.480047
  rotation 1 0 0 1.5708
  name "wall(9)"
  size 0.1 1 5
}
Wall {
  translation -3.73 9.9 0.480048
  rotation 1 0 0 1.5708
  name "wall(6)"
  size 0.1 1 5
}
Wall {
  translation 3.03 3.56 0.480033
  rotation 0.5773509358554485 0.5773489358556708 0.5773509358554485 2.0944
  name "wall(3)"
  size 0.1 1 7.5
}
Wall {
  translation 3.03 -3.12 0.480009
  rotation 0.5773509358554485 0.5773489358556708 0.5773509358554485 2.0944
  name "wall(7)"
  size 0.1 1 7.5
}
Wall {
  translation -9.77 -3.48 0.480007
  rotation 0.5773509358554485 0.5773489358556708 0.5773509358554485 2.0944
  name "wall(4)"
  size 0.1 1 6
}
Wall {
  translation -9.69 3.67 0.480038
  rotation 0.5773509358554485 0.5773489358556708 0.5773509358554485 2.0944
  name "wall(8)"
  size 0.1 1 6
}
Wall {
  translation -2.53 -8.41 0.269974
  rotation 1 0 0 1.5708
  name "wall(2)"
  size 0.1 0.5 1.5
}
Wall {
  translation -2.53 -8.32 0.269974
  rotation -0.5773509358554485 0.5773489358556708 0.5773509358554485 -2.094395307179586
  name "wall(10)"
  size 0.1 0.5 1
}
WallFollowingPioneer3dx {
  hidden position_0_0 -1.931646313035884e-05
  hidden position_0_1 5.051129853614383e-06
  hidden position_0_2 5.895945107883045e-06
  hidden position_0_3 1.4513176743611443e-07
  hidden rotation_1 0 0 -1 1.931645750327328e-05
  hidden position_1_0 7.12181746457087e-05
  hidden rotation_2 0 1 0 7.121817276062202e-05
  hidden translation_4 5.839106110753398e-10 0.165 -1.474704689960471e-15
  hidden rotation_4 0 1 0 5.051120002961656e-06
  hidden translation_9 6.815712544673308e-10 -0.165 -2.0093518862673854e-15
  hidden rotation_9 0 1 0 5.895966008099807e-06
  translation 0.4201932006431877 1.2323209878518668 0.09172938927347069
  rotation 0.12818252096001426 -0.9761124501326325 -0.17542441681933726 0.017943100263865884
  controller "robot_controller"
  extensionSlot [
    HingeJoint {
      device [
        RotationalMotor {
          name "front_wheel_motor"
        }
      ]
      endPoint Solid {
        translation 0.08999999999999996 1.9091658837180369e-07 -0.0499999999999728
        rotation 1 0 0 1.5708001451317672
        children [
          Shape {
            geometry Cylinder {
              height 0.02
              radius 0.04
            }
          }
        ]
        boundingObject Cylinder {
          height 0.02
          radius 0.04
        }
        physics Physics {
        }
      }
    }
    SharpGP2Y0A41SK0F {
      translation -0.18 0.13 0.15
      rotation 0 0 1 1.5708
    }
    Solid {
      translation 0 0 0.32
      children [
        Shape {
          appearance PBRAppearance {
          }
          geometry Cylinder {
            height 0.005
            radius 0.2
          }
        }
      ]
      name "khay_do_an"
      boundingObject Shape {
        appearance PBRAppearance {
        }
        geometry Cylinder {
          height 0.005
          radius 0.2
        }
      }
      physics Physics {
        density 11
        mass 0.5
      }
    }
    Solid {
      translation -0.01 0 0.53
      children [
        Shape {
          appearance PBRAppearance {
          }
          geometry Cylinder {
            height 0.005
            radius 0.2
          }
        }
      ]
      name "khay_do_an(1)"
      boundingObject Shape {
        appearance PBRAppearance {
        }
        geometry Cylinder {
          height 0.005
          radius 0.2
        }
      }
      physics Physics {
        density 1
        mass 0.1
      }
    }
    Solid {
      translation -0.11 0.15 0.34
      children [
        Shape {
          appearance PBRAppearance {
          }
          geometry Cylinder {
            height 0.4
            radius 0.01
          }
        }
      ]
      name "cot"
      boundingObject Shape {
        appearance PBRAppearance {
        }
        geometry Cylinder {
          height 0.4
          radius 0.01
        }
      }
      physics Physics {
        density 11
        mass 0.5
      }
    }
    Solid {
      translation 0.05 0.18 0.34
      children [
        Shape {
          appearance PBRAppearance {
          }
          geometry Cylinder {
            height 0.4
            radius 0.01
          }
        }
      ]
      name "cot(1)"
      boundingObject Shape {
        appearance PBRAppearance {
        }
        geometry Cylinder {
          height 0.4
          radius 0.01
        }
      }
      physics Physics {
        density 11
        mass 1.5
      }
    }
    Solid {
      translation -0.1 -0.16 0.34
      children [
        Shape {
          appearance PBRAppearance {
          }
          geometry Cylinder {
            height 0.4
            radius 0.01
          }
        }
      ]
      name "cot(2)"
      boundingObject Shape {
        appearance PBRAppearance {
        }
        geometry Cylinder {
          height 0.4
          radius 0.01
        }
      }
      physics Physics {
        density 11
        mass 1.5
      }
    }
    Solid {
      translation 0.07 -0.17 0.34
      children [
        Shape {
          appearance PBRAppearance {
          }
          geometry Cylinder {
            height 0.4
            radius 0.01
          }
        }
      ]
      name "cot(3)"
      boundingObject Shape {
        appearance PBRAppearance {
        }
        geometry Cylinder {
          height 0.4
          radius 0.01
        }
      }
      physics Physics {
        density 11
        mass 1.5
      }
    }
    Mir100UltrasonicSensor {
      translation 0.12 0.06 -0.04
      name "Mir100UltrasonicSensor(1)"
    }
    Mir100UltrasonicSensor {
      translation 0.12 -0.06 -0.04
    }
    Kinect {
      translation 0.15 0 0.54
    }
    SickLms291 {
      translation 0 0 0.2
    }
  ]
}
